{
 "cells": [
  {
   "cell_type": "code",
   "execution_count": 1,
   "metadata": {},
   "outputs": [],
   "source": [
    "import ray\n",
    "from ray import tune\n",
    "from sklearn.datasets import load_wine\n",
    "from sklearn.model_selection import train_test_split\n",
    "from sklearn.neural_network import MLPClassifier\n",
    "from sklearn.metrics import accuracy_score"
   ]
  },
  {
   "cell_type": "markdown",
   "metadata": {},
   "source": [
    "### Wine DataSet"
   ]
  },
  {
   "cell_type": "code",
   "execution_count": 2,
   "metadata": {},
   "outputs": [
    {
     "name": "stdout",
     "output_type": "stream",
     "text": [
      "(178, 13) (178,)\n",
      "(142, 13) (36, 13) (142,) (36,)\n"
     ]
    }
   ],
   "source": [
    "X, Y = load_wine(return_X_y=True)\n",
    "print(X.shape, Y.shape)\n",
    "X_train, X_test, y_train, y_test = train_test_split(X,Y, test_size=0.2)\n",
    "print(X_train.shape, X_test.shape, y_train.shape, y_test.shape)"
   ]
  },
  {
   "cell_type": "code",
   "execution_count": 3,
   "metadata": {},
   "outputs": [
    {
     "name": "stderr",
     "output_type": "stream",
     "text": [
      "c:\\Users\\Public\\anaconda3\\lib\\site-packages\\ray\\_private\\services.py:238: UserWarning: Not all Ray Dashboard dependencies were found. To use the dashboard please install Ray using `pip install ray[default]`. To disable this message, set RAY_DISABLE_IMPORT_WARNING env var to '1'.\n",
      "  warnings.warn(warning_message)\n"
     ]
    },
    {
     "data": {
      "text/html": [
       "== Status ==<br>Memory usage on this node: 6.1/7.9 GiB<br>Using FIFO scheduling algorithm.<br>Resources requested: 0/8 CPUs, 0/0 GPUs, 0.0/1.42 GiB heap, 0.0/0.71 GiB objects<br>Result logdir: C:\\Users\\Mohamed Ghallab\\ray_results\\my_experiment<br>Number of trials: 4/4 (4 PENDING)<br><table>\n",
       "<thead>\n",
       "<tr><th>Trial name         </th><th>status  </th><th>loc  </th><th style=\"text-align: right;\">  alpha</th><th>hidden_layer_sizes  </th></tr>\n",
       "</thead>\n",
       "<tbody>\n",
       "<tr><td>my_func_41690_00000</td><td>PENDING </td><td>     </td><td style=\"text-align: right;\">    0.1</td><td>(5, 2)              </td></tr>\n",
       "<tr><td>my_func_41690_00001</td><td>PENDING </td><td>     </td><td style=\"text-align: right;\">    0.2</td><td>(5, 2)              </td></tr>\n",
       "<tr><td>my_func_41690_00002</td><td>PENDING </td><td>     </td><td style=\"text-align: right;\">    0.1</td><td>(10, 2)             </td></tr>\n",
       "<tr><td>my_func_41690_00003</td><td>PENDING </td><td>     </td><td style=\"text-align: right;\">    0.2</td><td>(10, 2)             </td></tr>\n",
       "</tbody>\n",
       "</table><br><br>"
      ],
      "text/plain": [
       "<IPython.core.display.HTML object>"
      ]
     },
     "metadata": {},
     "output_type": "display_data"
    },
    {
     "name": "stderr",
     "output_type": "stream",
     "text": [
      "2022-05-10 04:31:11,549\tERROR syncer.py:72 -- Log sync requires rsync to be installed.\n",
      "2022-05-10 04:31:14,291\tINFO logger.py:697 -- Removed the following hyperparameter values when logging to tensorboard: {'hidden_layer_sizes': (5, 2)}\n"
     ]
    },
    {
     "name": "stdout",
     "output_type": "stream",
     "text": [
      "Result for my_func_41690_00000:\n",
      "  _metric:\n",
      "    alpha: 0.1\n",
      "    hidden_layer_sizes:\n",
      "    - 5\n",
      "    - 2\n",
      "  date: 2022-05-10_04-31-14\n",
      "  done: false\n",
      "  experiment_id: 908683481dd24051bbb8433973856b5e\n",
      "  hostname: Ghallab\n",
      "  iterations_since_restore: 1\n",
      "  mean_accuracy: 0.5833333333333334\n",
      "  node_ip: 192.168.1.105\n",
      "  pid: 14268\n",
      "  time_since_restore: 0.24509358406066895\n",
      "  time_this_iter_s: 0.24509358406066895\n",
      "  time_total_s: 0.24509358406066895\n",
      "  timestamp: 1652149874\n",
      "  timesteps_since_restore: 0\n",
      "  training_iteration: 1\n",
      "  trial_id: '41690_00000'\n",
      "  \n",
      "Result for my_func_41690_00000:\n",
      "  _metric:\n",
      "    alpha: 0.1\n",
      "    hidden_layer_sizes:\n",
      "    - 5\n",
      "    - 2\n",
      "  date: 2022-05-10_04-31-14\n",
      "  done: true\n",
      "  experiment_id: 908683481dd24051bbb8433973856b5e\n",
      "  experiment_tag: 0_alpha=0.1,hidden_layer_sizes=(5, 2)\n",
      "  hostname: Ghallab\n",
      "  iterations_since_restore: 1\n",
      "  mean_accuracy: 0.5833333333333334\n",
      "  node_ip: 192.168.1.105\n",
      "  pid: 14268\n",
      "  time_since_restore: 0.24509358406066895\n",
      "  time_this_iter_s: 0.24509358406066895\n",
      "  time_total_s: 0.24509358406066895\n",
      "  timestamp: 1652149874\n",
      "  timesteps_since_restore: 0\n",
      "  training_iteration: 1\n",
      "  trial_id: '41690_00000'\n",
      "  \n",
      "\u001b[2m\u001b[36m(pid=14268)\u001b[0m 0.5833333333333334\n"
     ]
    },
    {
     "name": "stderr",
     "output_type": "stream",
     "text": [
      "\u001b[2m\u001b[36m(pid=14268)\u001b[0m Windows fatal exception: access violation\n",
      "\u001b[2m\u001b[36m(pid=14268)\u001b[0m \n",
      "2022-05-10 04:31:14,497\tINFO logger.py:697 -- Removed the following hyperparameter values when logging to tensorboard: {'hidden_layer_sizes': (10, 2)}\n",
      "\u001b[2m\u001b[36m(pid=18200)\u001b[0m Windows fatal exception: access violation\n",
      "\u001b[2m\u001b[36m(pid=18200)\u001b[0m \n"
     ]
    },
    {
     "name": "stdout",
     "output_type": "stream",
     "text": [
      "Result for my_func_41690_00003:\n",
      "  _metric:\n",
      "    alpha: 0.2\n",
      "    hidden_layer_sizes:\n",
      "    - 10\n",
      "    - 2\n",
      "  date: 2022-05-10_04-31-14\n",
      "  done: true\n",
      "  experiment_id: 1b6cc960242648509bc7e1d9d57c4a0a\n",
      "  hostname: Ghallab\n",
      "  iterations_since_restore: 1\n",
      "  mean_accuracy: 0.9444444444444444\n",
      "  node_ip: 192.168.1.105\n",
      "  pid: 18200\n",
      "  time_since_restore: 0.4774773120880127\n",
      "  time_this_iter_s: 0.4774773120880127\n",
      "  time_total_s: 0.4774773120880127\n",
      "  timestamp: 1652149874\n",
      "  timesteps_since_restore: 0\n",
      "  training_iteration: 1\n",
      "  trial_id: '41690_00003'\n",
      "  \n"
     ]
    },
    {
     "name": "stderr",
     "output_type": "stream",
     "text": [
      "2022-05-10 04:31:15,627\tINFO logger.py:697 -- Removed the following hyperparameter values when logging to tensorboard: {'hidden_layer_sizes': (5, 2)}\n",
      "2022-05-10 04:31:15,656\tINFO logger.py:697 -- Removed the following hyperparameter values when logging to tensorboard: {'hidden_layer_sizes': (10, 2)}\n"
     ]
    },
    {
     "name": "stdout",
     "output_type": "stream",
     "text": [
      "Result for my_func_41690_00001:\n",
      "  _metric:\n",
      "    alpha: 0.2\n",
      "    hidden_layer_sizes:\n",
      "    - 5\n",
      "    - 2\n",
      "  date: 2022-05-10_04-31-15\n",
      "  done: true\n",
      "  experiment_id: d91dffcf52284d798e3d25e5919d7081\n",
      "  hostname: Ghallab\n",
      "  iterations_since_restore: 1\n",
      "  mean_accuracy: 0.7222222222222222\n",
      "  node_ip: 192.168.1.105\n",
      "  pid: 23580\n",
      "  time_since_restore: 1.5964789390563965\n",
      "  time_this_iter_s: 1.5964789390563965\n",
      "  time_total_s: 1.5964789390563965\n",
      "  timestamp: 1652149875\n",
      "  timesteps_since_restore: 0\n",
      "  training_iteration: 1\n",
      "  trial_id: '41690_00001'\n",
      "  \n",
      "Result for my_func_41690_00002:\n",
      "  _metric:\n",
      "    alpha: 0.1\n",
      "    hidden_layer_sizes:\n",
      "    - 10\n",
      "    - 2\n",
      "  date: 2022-05-10_04-31-15\n",
      "  done: true\n",
      "  experiment_id: efcff176a977430ba0570f82b03d823f\n",
      "  hostname: Ghallab\n",
      "  iterations_since_restore: 1\n",
      "  mean_accuracy: 0.8888888888888888\n",
      "  node_ip: 192.168.1.105\n",
      "  pid: 23388\n",
      "  time_since_restore: 1.605454444885254\n",
      "  time_this_iter_s: 1.605454444885254\n",
      "  time_total_s: 1.605454444885254\n",
      "  timestamp: 1652149875\n",
      "  timesteps_since_restore: 0\n",
      "  training_iteration: 1\n",
      "  trial_id: '41690_00002'\n",
      "  \n"
     ]
    },
    {
     "name": "stderr",
     "output_type": "stream",
     "text": [
      "\u001b[2m\u001b[36m(pid=23388)\u001b[0m Windows fatal exception: access violation\n",
      "\u001b[2m\u001b[36m(pid=23388)\u001b[0m \n",
      "\u001b[2m\u001b[36m(pid=23580)\u001b[0m Windows fatal exception: access violation\n",
      "\u001b[2m\u001b[36m(pid=23580)\u001b[0m \n"
     ]
    },
    {
     "data": {
      "text/html": [
       "== Status ==<br>Memory usage on this node: 5.9/7.9 GiB<br>Using FIFO scheduling algorithm.<br>Resources requested: 0/8 CPUs, 0/0 GPUs, 0.0/1.42 GiB heap, 0.0/0.71 GiB objects<br>Result logdir: C:\\Users\\Mohamed Ghallab\\ray_results\\my_experiment<br>Number of trials: 4/4 (4 TERMINATED)<br><table>\n",
       "<thead>\n",
       "<tr><th>Trial name         </th><th>status    </th><th>loc  </th><th style=\"text-align: right;\">  alpha</th><th>hidden_layer_sizes  </th><th style=\"text-align: right;\">     acc</th><th style=\"text-align: right;\">  iter</th><th style=\"text-align: right;\">  total time (s)</th></tr>\n",
       "</thead>\n",
       "<tbody>\n",
       "<tr><td>my_func_41690_00000</td><td>TERMINATED</td><td>     </td><td style=\"text-align: right;\">    0.1</td><td>(5, 2)              </td><td style=\"text-align: right;\">0.583333</td><td style=\"text-align: right;\">     1</td><td style=\"text-align: right;\">        0.245094</td></tr>\n",
       "<tr><td>my_func_41690_00001</td><td>TERMINATED</td><td>     </td><td style=\"text-align: right;\">    0.2</td><td>(5, 2)              </td><td style=\"text-align: right;\">0.722222</td><td style=\"text-align: right;\">     1</td><td style=\"text-align: right;\">        1.59648 </td></tr>\n",
       "<tr><td>my_func_41690_00002</td><td>TERMINATED</td><td>     </td><td style=\"text-align: right;\">    0.1</td><td>(10, 2)             </td><td style=\"text-align: right;\">0.888889</td><td style=\"text-align: right;\">     1</td><td style=\"text-align: right;\">        1.60545 </td></tr>\n",
       "<tr><td>my_func_41690_00003</td><td>TERMINATED</td><td>     </td><td style=\"text-align: right;\">    0.2</td><td>(10, 2)             </td><td style=\"text-align: right;\">0.944444</td><td style=\"text-align: right;\">     1</td><td style=\"text-align: right;\">        0.477477</td></tr>\n",
       "</tbody>\n",
       "</table><br><br>"
      ],
      "text/plain": [
       "<IPython.core.display.HTML object>"
      ]
     },
     "metadata": {},
     "output_type": "display_data"
    },
    {
     "name": "stderr",
     "output_type": "stream",
     "text": [
      "2022-05-10 04:31:15,872\tINFO tune.py:561 -- Total run time: 4.65 seconds (4.32 seconds for the tuning loop).\n",
      "\u001b[2m\u001b[36m(pid=None)\u001b[0m [2022-05-10 04:37:14,911 C 21604 4136] redis_client.cc:87:  Check failed: under_retry_limit Expected 1 Redis shard addresses, found 2\n",
      "\u001b[2m\u001b[36m(pid=None)\u001b[0m *** StackTrace Information ***\n",
      "\u001b[2m\u001b[36m(pid=None)\u001b[0m \n",
      "\u001b[2m\u001b[36m(pid=15548)\u001b[0m 2022-05-10 04:37:22,665\tERROR function_runner.py:266 -- Runner Thread raised error.\n",
      "\u001b[2m\u001b[36m(pid=15548)\u001b[0m Traceback (most recent call last):\n",
      "\u001b[2m\u001b[36m(pid=15548)\u001b[0m   File \"c:\\Users\\Public\\anaconda3\\lib\\site-packages\\ray\\tune\\function_runner.py\", line 260, in run\n",
      "\u001b[2m\u001b[36m(pid=15548)\u001b[0m     self._entrypoint()\n",
      "\u001b[2m\u001b[36m(pid=15548)\u001b[0m   File \"c:\\Users\\Public\\anaconda3\\lib\\site-packages\\ray\\tune\\function_runner.py\", line 328, in entrypoint\n",
      "\u001b[2m\u001b[36m(pid=15548)\u001b[0m     return self._trainable_func(self.config, self._status_reporter,\n",
      "\u001b[2m\u001b[36m(pid=15548)\u001b[0m   File \"c:\\Users\\Public\\anaconda3\\lib\\site-packages\\ray\\tune\\function_runner.py\", line 594, in _trainable_func\n",
      "\u001b[2m\u001b[36m(pid=15548)\u001b[0m     output = fn()\n",
      "\u001b[2m\u001b[36m(pid=15548)\u001b[0m   File \"<ipython-input-8-f1e274a7315c>\", line 4, in my_func\n",
      "\u001b[2m\u001b[36m(pid=15548)\u001b[0m IndexError: tuple index out of range\n",
      "\u001b[2m\u001b[36m(pid=15548)\u001b[0m Exception in thread Thread-2:\n",
      "\u001b[2m\u001b[36m(pid=15548)\u001b[0m Traceback (most recent call last):\n",
      "\u001b[2m\u001b[36m(pid=15548)\u001b[0m   File \"c:\\Users\\Public\\anaconda3\\lib\\threading.py\", line 932, in _bootstrap_inner\n",
      "\u001b[2m\u001b[36m(pid=15548)\u001b[0m     self.run()\n",
      "\u001b[2m\u001b[36m(pid=15548)\u001b[0m   File \"c:\\Users\\Public\\anaconda3\\lib\\site-packages\\ray\\tune\\function_runner.py\", line 279, in run\n",
      "\u001b[2m\u001b[36m(pid=15548)\u001b[0m     raise e\n",
      "\u001b[2m\u001b[36m(pid=15548)\u001b[0m   File \"c:\\Users\\Public\\anaconda3\\lib\\site-packages\\ray\\tune\\function_runner.py\", line 260, in run\n",
      "\u001b[2m\u001b[36m(pid=15548)\u001b[0m     self._entrypoint()\n",
      "\u001b[2m\u001b[36m(pid=15548)\u001b[0m   File \"c:\\Users\\Public\\anaconda3\\lib\\site-packages\\ray\\tune\\function_runner.py\", line 328, in entrypoint\n",
      "\u001b[2m\u001b[36m(pid=15548)\u001b[0m     return self._trainable_func(self.config, self._status_reporter,\n",
      "\u001b[2m\u001b[36m(pid=15548)\u001b[0m   File \"c:\\Users\\Public\\anaconda3\\lib\\site-packages\\ray\\tune\\function_runner.py\", line 594, in _trainable_func\n",
      "\u001b[2m\u001b[36m(pid=15548)\u001b[0m     output = fn()\n",
      "\u001b[2m\u001b[36m(pid=15548)\u001b[0m   File \"<ipython-input-8-f1e274a7315c>\", line 4, in my_func\n",
      "\u001b[2m\u001b[36m(pid=15548)\u001b[0m IndexError: tuple index out of range\n",
      "\u001b[2m\u001b[36m(pid=17932)\u001b[0m 2022-05-10 04:37:22,665\tERROR function_runner.py:266 -- Runner Thread raised error.\n",
      "\u001b[2m\u001b[36m(pid=17932)\u001b[0m Traceback (most recent call last):\n",
      "\u001b[2m\u001b[36m(pid=17932)\u001b[0m   File \"c:\\Users\\Public\\anaconda3\\lib\\site-packages\\ray\\tune\\function_runner.py\", line 260, in run\n",
      "\u001b[2m\u001b[36m(pid=17932)\u001b[0m     self._entrypoint()\n",
      "\u001b[2m\u001b[36m(pid=17932)\u001b[0m   File \"c:\\Users\\Public\\anaconda3\\lib\\site-packages\\ray\\tune\\function_runner.py\", line 328, in entrypoint\n",
      "\u001b[2m\u001b[36m(pid=17932)\u001b[0m     return self._trainable_func(self.config, self._status_reporter,\n",
      "\u001b[2m\u001b[36m(pid=17932)\u001b[0m   File \"c:\\Users\\Public\\anaconda3\\lib\\site-packages\\ray\\tune\\function_runner.py\", line 594, in _trainable_func\n",
      "\u001b[2m\u001b[36m(pid=17932)\u001b[0m     output = fn()\n",
      "\u001b[2m\u001b[36m(pid=17932)\u001b[0m   File \"<ipython-input-8-f1e274a7315c>\", line 4, in my_func\n",
      "\u001b[2m\u001b[36m(pid=17932)\u001b[0m IndexError: tuple index out of range\n",
      "\u001b[2m\u001b[36m(pid=17932)\u001b[0m Exception in thread Thread-2:\n",
      "\u001b[2m\u001b[36m(pid=17932)\u001b[0m Traceback (most recent call last):\n",
      "\u001b[2m\u001b[36m(pid=17932)\u001b[0m   File \"c:\\Users\\Public\\anaconda3\\lib\\threading.py\", line 932, in _bootstrap_inner\n",
      "\u001b[2m\u001b[36m(pid=17932)\u001b[0m     self.run()\n",
      "\u001b[2m\u001b[36m(pid=17932)\u001b[0m   File \"c:\\Users\\Public\\anaconda3\\lib\\site-packages\\ray\\tune\\function_runner.py\", line 279, in run\n",
      "\u001b[2m\u001b[36m(pid=17932)\u001b[0m     raise e\n",
      "\u001b[2m\u001b[36m(pid=17932)\u001b[0m   File \"c:\\Users\\Public\\anaconda3\\lib\\site-packages\\ray\\tune\\function_runner.py\", line 260, in run\n",
      "\u001b[2m\u001b[36m(pid=17932)\u001b[0m     self._entrypoint()\n",
      "\u001b[2m\u001b[36m(pid=17932)\u001b[0m   File \"c:\\Users\\Public\\anaconda3\\lib\\site-packages\\ray\\tune\\function_runner.py\", line 328, in entrypoint\n",
      "\u001b[2m\u001b[36m(pid=17932)\u001b[0m     return self._trainable_func(self.config, self._status_reporter,\n",
      "\u001b[2m\u001b[36m(pid=17932)\u001b[0m   File \"c:\\Users\\Public\\anaconda3\\lib\\site-packages\\ray\\tune\\function_runner.py\", line 594, in _trainable_func\n",
      "\u001b[2m\u001b[36m(pid=17932)\u001b[0m     output = fn()\n",
      "\u001b[2m\u001b[36m(pid=17932)\u001b[0m   File \"<ipython-input-8-f1e274a7315c>\", line 4, in my_func\n",
      "\u001b[2m\u001b[36m(pid=17932)\u001b[0m IndexError: tuple index out of range\n",
      "\u001b[2m\u001b[36m(pid=8312)\u001b[0m 2022-05-10 04:37:22,665\tERROR function_runner.py:266 -- Runner Thread raised error.\n",
      "\u001b[2m\u001b[36m(pid=8312)\u001b[0m Traceback (most recent call last):\n",
      "\u001b[2m\u001b[36m(pid=8312)\u001b[0m   File \"c:\\Users\\Public\\anaconda3\\lib\\site-packages\\ray\\tune\\function_runner.py\", line 260, in run\n",
      "\u001b[2m\u001b[36m(pid=8312)\u001b[0m     self._entrypoint()\n",
      "\u001b[2m\u001b[36m(pid=8312)\u001b[0m   File \"c:\\Users\\Public\\anaconda3\\lib\\site-packages\\ray\\tune\\function_runner.py\", line 328, in entrypoint\n",
      "\u001b[2m\u001b[36m(pid=8312)\u001b[0m     return self._trainable_func(self.config, self._status_reporter,\n",
      "\u001b[2m\u001b[36m(pid=8312)\u001b[0m   File \"c:\\Users\\Public\\anaconda3\\lib\\site-packages\\ray\\tune\\function_runner.py\", line 594, in _trainable_func\n",
      "\u001b[2m\u001b[36m(pid=8312)\u001b[0m     output = fn()\n",
      "\u001b[2m\u001b[36m(pid=8312)\u001b[0m   File \"<ipython-input-8-f1e274a7315c>\", line 4, in my_func\n",
      "\u001b[2m\u001b[36m(pid=8312)\u001b[0m IndexError: tuple index out of range\n",
      "\u001b[2m\u001b[36m(pid=8312)\u001b[0m Exception in thread Thread-2:\n",
      "\u001b[2m\u001b[36m(pid=8312)\u001b[0m Traceback (most recent call last):\n",
      "\u001b[2m\u001b[36m(pid=8312)\u001b[0m   File \"c:\\Users\\Public\\anaconda3\\lib\\threading.py\", line 932, in _bootstrap_inner\n",
      "\u001b[2m\u001b[36m(pid=8312)\u001b[0m     self.run()\n",
      "\u001b[2m\u001b[36m(pid=8312)\u001b[0m   File \"c:\\Users\\Public\\anaconda3\\lib\\site-packages\\ray\\tune\\function_runner.py\", line 279, in run\n",
      "\u001b[2m\u001b[36m(pid=8312)\u001b[0m     raise e\n",
      "\u001b[2m\u001b[36m(pid=8312)\u001b[0m   File \"c:\\Users\\Public\\anaconda3\\lib\\site-packages\\ray\\tune\\function_runner.py\", line 260, in run\n",
      "\u001b[2m\u001b[36m(pid=8312)\u001b[0m     self._entrypoint()\n",
      "\u001b[2m\u001b[36m(pid=8312)\u001b[0m   File \"c:\\Users\\Public\\anaconda3\\lib\\site-packages\\ray\\tune\\function_runner.py\", line 328, in entrypoint\n",
      "\u001b[2m\u001b[36m(pid=8312)\u001b[0m     return self._trainable_func(self.config, self._status_reporter,\n",
      "\u001b[2m\u001b[36m(pid=8312)\u001b[0m   File \"c:\\Users\\Public\\anaconda3\\lib\\site-packages\\ray\\tune\\function_runner.py\", line 594, in _trainable_func\n",
      "\u001b[2m\u001b[36m(pid=8312)\u001b[0m     output = fn()\n",
      "\u001b[2m\u001b[36m(pid=8312)\u001b[0m   File \"<ipython-input-8-f1e274a7315c>\", line 4, in my_func\n",
      "\u001b[2m\u001b[36m(pid=8312)\u001b[0m IndexError: tuple index out of range\n",
      "\u001b[2m\u001b[36m(pid=7052)\u001b[0m 2022-05-10 04:37:22,666\tERROR function_runner.py:266 -- Runner Thread raised error.\n",
      "\u001b[2m\u001b[36m(pid=7052)\u001b[0m Traceback (most recent call last):\n",
      "\u001b[2m\u001b[36m(pid=7052)\u001b[0m   File \"c:\\Users\\Public\\anaconda3\\lib\\site-packages\\ray\\tune\\function_runner.py\", line 260, in run\n",
      "\u001b[2m\u001b[36m(pid=7052)\u001b[0m     self._entrypoint()\n",
      "\u001b[2m\u001b[36m(pid=7052)\u001b[0m   File \"c:\\Users\\Public\\anaconda3\\lib\\site-packages\\ray\\tune\\function_runner.py\", line 328, in entrypoint\n",
      "\u001b[2m\u001b[36m(pid=7052)\u001b[0m     return self._trainable_func(self.config, self._status_reporter,\n",
      "\u001b[2m\u001b[36m(pid=7052)\u001b[0m   File \"c:\\Users\\Public\\anaconda3\\lib\\site-packages\\ray\\tune\\function_runner.py\", line 594, in _trainable_func\n",
      "\u001b[2m\u001b[36m(pid=7052)\u001b[0m     output = fn()\n",
      "\u001b[2m\u001b[36m(pid=7052)\u001b[0m   File \"<ipython-input-8-f1e274a7315c>\", line 4, in my_func\n",
      "\u001b[2m\u001b[36m(pid=7052)\u001b[0m IndexError: tuple index out of range\n",
      "\u001b[2m\u001b[36m(pid=7052)\u001b[0m Exception in thread Thread-2:\n",
      "\u001b[2m\u001b[36m(pid=7052)\u001b[0m Traceback (most recent call last):\n",
      "\u001b[2m\u001b[36m(pid=7052)\u001b[0m   File \"c:\\Users\\Public\\anaconda3\\lib\\threading.py\", line 932, in _bootstrap_inner\n",
      "\u001b[2m\u001b[36m(pid=7052)\u001b[0m     self.run()\n",
      "\u001b[2m\u001b[36m(pid=7052)\u001b[0m   File \"c:\\Users\\Public\\anaconda3\\lib\\site-packages\\ray\\tune\\function_runner.py\", line 279, in run\n",
      "\u001b[2m\u001b[36m(pid=7052)\u001b[0m     raise e\n",
      "\u001b[2m\u001b[36m(pid=7052)\u001b[0m   File \"c:\\Users\\Public\\anaconda3\\lib\\site-packages\\ray\\tune\\function_runner.py\", line 260, in run\n",
      "\u001b[2m\u001b[36m(pid=7052)\u001b[0m     self._entrypoint()\n",
      "\u001b[2m\u001b[36m(pid=7052)\u001b[0m   File \"c:\\Users\\Public\\anaconda3\\lib\\site-packages\\ray\\tune\\function_runner.py\", line 328, in entrypoint\n",
      "\u001b[2m\u001b[36m(pid=7052)\u001b[0m     return self._trainable_func(self.config, self._status_reporter,\n",
      "\u001b[2m\u001b[36m(pid=7052)\u001b[0m   File \"c:\\Users\\Public\\anaconda3\\lib\\site-packages\\ray\\tune\\function_runner.py\", line 594, in _trainable_func\n",
      "\u001b[2m\u001b[36m(pid=7052)\u001b[0m     output = fn()\n",
      "\u001b[2m\u001b[36m(pid=7052)\u001b[0m   File \"<ipython-input-8-f1e274a7315c>\", line 4, in my_func\n",
      "\u001b[2m\u001b[36m(pid=7052)\u001b[0m IndexError: tuple index out of range\n",
      "\u001b[2m\u001b[36m(pid=15548)\u001b[0m Windows fatal exception: access violation\n",
      "\u001b[2m\u001b[36m(pid=15548)\u001b[0m \n",
      "\u001b[2m\u001b[36m(pid=17932)\u001b[0m Windows fatal exception: access violation\n",
      "\u001b[2m\u001b[36m(pid=17932)\u001b[0m \n",
      "\u001b[2m\u001b[36m(pid=8312)\u001b[0m Windows fatal exception: access violation\n",
      "\u001b[2m\u001b[36m(pid=8312)\u001b[0m \n",
      "\u001b[2m\u001b[36m(pid=7052)\u001b[0m Windows fatal exception: access violation\n",
      "\u001b[2m\u001b[36m(pid=7052)\u001b[0m \n",
      "\u001b[2m\u001b[36m(pid=6732)\u001b[0m 2022-05-10 04:39:07,759\tERROR function_runner.py:266 -- Runner Thread raised error.\n",
      "\u001b[2m\u001b[36m(pid=6732)\u001b[0m Traceback (most recent call last):\n",
      "\u001b[2m\u001b[36m(pid=6732)\u001b[0m   File \"c:\\Users\\Public\\anaconda3\\lib\\site-packages\\ray\\tune\\function_runner.py\", line 260, in run\n",
      "\u001b[2m\u001b[36m(pid=6732)\u001b[0m     self._entrypoint()\n",
      "\u001b[2m\u001b[36m(pid=6732)\u001b[0m   File \"c:\\Users\\Public\\anaconda3\\lib\\site-packages\\ray\\tune\\function_runner.py\", line 328, in entrypoint\n",
      "\u001b[2m\u001b[36m(pid=6732)\u001b[0m     return self._trainable_func(self.config, self._status_reporter,\n",
      "\u001b[2m\u001b[36m(pid=6732)\u001b[0m   File \"c:\\Users\\Public\\anaconda3\\lib\\site-packages\\ray\\tune\\function_runner.py\", line 594, in _trainable_func\n",
      "\u001b[2m\u001b[36m(pid=6732)\u001b[0m     output = fn()\n",
      "\u001b[2m\u001b[36m(pid=6732)\u001b[0m   File \"<ipython-input-9-d9db0bddfedd>\", line 4, in my_func\n",
      "\u001b[2m\u001b[36m(pid=6732)\u001b[0m IndexError: tuple index out of range\n",
      "\u001b[2m\u001b[36m(pid=6732)\u001b[0m Exception in thread Thread-2:\n",
      "\u001b[2m\u001b[36m(pid=6732)\u001b[0m Traceback (most recent call last):\n",
      "\u001b[2m\u001b[36m(pid=6732)\u001b[0m   File \"c:\\Users\\Public\\anaconda3\\lib\\threading.py\", line 932, in _bootstrap_inner\n",
      "\u001b[2m\u001b[36m(pid=6732)\u001b[0m     self.run()\n",
      "\u001b[2m\u001b[36m(pid=6732)\u001b[0m   File \"c:\\Users\\Public\\anaconda3\\lib\\site-packages\\ray\\tune\\function_runner.py\", line 279, in run\n",
      "\u001b[2m\u001b[36m(pid=6732)\u001b[0m     raise e\n",
      "\u001b[2m\u001b[36m(pid=6732)\u001b[0m   File \"c:\\Users\\Public\\anaconda3\\lib\\site-packages\\ray\\tune\\function_runner.py\", line 260, in run\n",
      "\u001b[2m\u001b[36m(pid=6732)\u001b[0m     self._entrypoint()\n",
      "\u001b[2m\u001b[36m(pid=6732)\u001b[0m   File \"c:\\Users\\Public\\anaconda3\\lib\\site-packages\\ray\\tune\\function_runner.py\", line 328, in entrypoint\n",
      "\u001b[2m\u001b[36m(pid=6732)\u001b[0m     return self._trainable_func(self.config, self._status_reporter,\n",
      "\u001b[2m\u001b[36m(pid=6732)\u001b[0m   File \"c:\\Users\\Public\\anaconda3\\lib\\site-packages\\ray\\tune\\function_runner.py\", line 594, in _trainable_func\n",
      "\u001b[2m\u001b[36m(pid=6732)\u001b[0m     output = fn()\n",
      "\u001b[2m\u001b[36m(pid=6732)\u001b[0m   File \"<ipython-input-9-d9db0bddfedd>\", line 4, in my_func\n",
      "\u001b[2m\u001b[36m(pid=6732)\u001b[0m IndexError: tuple index out of range\n",
      "\u001b[2m\u001b[36m(pid=18288)\u001b[0m 2022-05-10 04:39:07,797\tERROR function_runner.py:266 -- Runner Thread raised error.\n",
      "\u001b[2m\u001b[36m(pid=18288)\u001b[0m Traceback (most recent call last):\n",
      "\u001b[2m\u001b[36m(pid=18288)\u001b[0m   File \"c:\\Users\\Public\\anaconda3\\lib\\site-packages\\ray\\tune\\function_runner.py\", line 260, in run\n",
      "\u001b[2m\u001b[36m(pid=18288)\u001b[0m     self._entrypoint()\n",
      "\u001b[2m\u001b[36m(pid=18288)\u001b[0m   File \"c:\\Users\\Public\\anaconda3\\lib\\site-packages\\ray\\tune\\function_runner.py\", line 328, in entrypoint\n",
      "\u001b[2m\u001b[36m(pid=18288)\u001b[0m     return self._trainable_func(self.config, self._status_reporter,\n",
      "\u001b[2m\u001b[36m(pid=18288)\u001b[0m   File \"c:\\Users\\Public\\anaconda3\\lib\\site-packages\\ray\\tune\\function_runner.py\", line 594, in _trainable_func\n",
      "\u001b[2m\u001b[36m(pid=18288)\u001b[0m     output = fn()\n",
      "\u001b[2m\u001b[36m(pid=18288)\u001b[0m   File \"<ipython-input-9-d9db0bddfedd>\", line 4, in my_func\n",
      "\u001b[2m\u001b[36m(pid=18288)\u001b[0m IndexError: tuple index out of range\n",
      "\u001b[2m\u001b[36m(pid=18288)\u001b[0m Exception in thread Thread-2:\n",
      "\u001b[2m\u001b[36m(pid=18288)\u001b[0m Traceback (most recent call last):\n",
      "\u001b[2m\u001b[36m(pid=18288)\u001b[0m   File \"c:\\Users\\Public\\anaconda3\\lib\\threading.py\", line 932, in _bootstrap_inner\n",
      "\u001b[2m\u001b[36m(pid=18288)\u001b[0m     self.run()\n",
      "\u001b[2m\u001b[36m(pid=18288)\u001b[0m   File \"c:\\Users\\Public\\anaconda3\\lib\\site-packages\\ray\\tune\\function_runner.py\", line 279, in run\n",
      "\u001b[2m\u001b[36m(pid=18288)\u001b[0m     raise e\n",
      "\u001b[2m\u001b[36m(pid=18288)\u001b[0m   File \"c:\\Users\\Public\\anaconda3\\lib\\site-packages\\ray\\tune\\function_runner.py\", line 260, in run\n",
      "\u001b[2m\u001b[36m(pid=18288)\u001b[0m     self._entrypoint()\n",
      "\u001b[2m\u001b[36m(pid=18288)\u001b[0m   File \"c:\\Users\\Public\\anaconda3\\lib\\site-packages\\ray\\tune\\function_runner.py\", line 328, in entrypoint\n",
      "\u001b[2m\u001b[36m(pid=18288)\u001b[0m     return self._trainable_func(self.config, self._status_reporter,\n",
      "\u001b[2m\u001b[36m(pid=18288)\u001b[0m   File \"c:\\Users\\Public\\anaconda3\\lib\\site-packages\\ray\\tune\\function_runner.py\", line 594, in _trainable_func\n",
      "\u001b[2m\u001b[36m(pid=18288)\u001b[0m     output = fn()\n",
      "\u001b[2m\u001b[36m(pid=18288)\u001b[0m   File \"<ipython-input-9-d9db0bddfedd>\", line 4, in my_func\n",
      "\u001b[2m\u001b[36m(pid=18288)\u001b[0m IndexError: tuple index out of range\n",
      "\u001b[2m\u001b[36m(pid=18572)\u001b[0m 2022-05-10 04:39:07,780\tERROR function_runner.py:266 -- Runner Thread raised error.\n",
      "\u001b[2m\u001b[36m(pid=18572)\u001b[0m Traceback (most recent call last):\n",
      "\u001b[2m\u001b[36m(pid=18572)\u001b[0m   File \"c:\\Users\\Public\\anaconda3\\lib\\site-packages\\ray\\tune\\function_runner.py\", line 260, in run\n",
      "\u001b[2m\u001b[36m(pid=18572)\u001b[0m     self._entrypoint()\n",
      "\u001b[2m\u001b[36m(pid=18572)\u001b[0m   File \"c:\\Users\\Public\\anaconda3\\lib\\site-packages\\ray\\tune\\function_runner.py\", line 328, in entrypoint\n",
      "\u001b[2m\u001b[36m(pid=18572)\u001b[0m     return self._trainable_func(self.config, self._status_reporter,\n",
      "\u001b[2m\u001b[36m(pid=18572)\u001b[0m   File \"c:\\Users\\Public\\anaconda3\\lib\\site-packages\\ray\\tune\\function_runner.py\", line 594, in _trainable_func\n",
      "\u001b[2m\u001b[36m(pid=18572)\u001b[0m     output = fn()\n",
      "\u001b[2m\u001b[36m(pid=18572)\u001b[0m   File \"<ipython-input-9-d9db0bddfedd>\", line 4, in my_func\n",
      "\u001b[2m\u001b[36m(pid=18572)\u001b[0m IndexError: tuple index out of range\n",
      "\u001b[2m\u001b[36m(pid=18572)\u001b[0m Exception in thread Thread-2:\n",
      "\u001b[2m\u001b[36m(pid=18572)\u001b[0m Traceback (most recent call last):\n",
      "\u001b[2m\u001b[36m(pid=18572)\u001b[0m   File \"c:\\Users\\Public\\anaconda3\\lib\\threading.py\", line 932, in _bootstrap_inner\n",
      "\u001b[2m\u001b[36m(pid=18572)\u001b[0m     self.run()\n",
      "\u001b[2m\u001b[36m(pid=18572)\u001b[0m   File \"c:\\Users\\Public\\anaconda3\\lib\\site-packages\\ray\\tune\\function_runner.py\", line 279, in run\n",
      "\u001b[2m\u001b[36m(pid=18572)\u001b[0m     raise e\n",
      "\u001b[2m\u001b[36m(pid=18572)\u001b[0m   File \"c:\\Users\\Public\\anaconda3\\lib\\site-packages\\ray\\tune\\function_runner.py\", line 260, in run\n",
      "\u001b[2m\u001b[36m(pid=18572)\u001b[0m     self._entrypoint()\n",
      "\u001b[2m\u001b[36m(pid=18572)\u001b[0m   File \"c:\\Users\\Public\\anaconda3\\lib\\site-packages\\ray\\tune\\function_runner.py\", line 328, in entrypoint\n",
      "\u001b[2m\u001b[36m(pid=18572)\u001b[0m     return self._trainable_func(self.config, self._status_reporter,\n",
      "\u001b[2m\u001b[36m(pid=18572)\u001b[0m   File \"c:\\Users\\Public\\anaconda3\\lib\\site-packages\\ray\\tune\\function_runner.py\", line 594, in _trainable_func\n",
      "\u001b[2m\u001b[36m(pid=18572)\u001b[0m     output = fn()\n",
      "\u001b[2m\u001b[36m(pid=18572)\u001b[0m   File \"<ipython-input-9-d9db0bddfedd>\", line 4, in my_func\n",
      "\u001b[2m\u001b[36m(pid=18572)\u001b[0m IndexError: tuple index out of range\n",
      "\u001b[2m\u001b[36m(pid=13380)\u001b[0m 2022-05-10 04:39:07,789\tERROR function_runner.py:266 -- Runner Thread raised error.\n",
      "\u001b[2m\u001b[36m(pid=13380)\u001b[0m Traceback (most recent call last):\n",
      "\u001b[2m\u001b[36m(pid=13380)\u001b[0m   File \"c:\\Users\\Public\\anaconda3\\lib\\site-packages\\ray\\tune\\function_runner.py\", line 260, in run\n",
      "\u001b[2m\u001b[36m(pid=13380)\u001b[0m     self._entrypoint()\n",
      "\u001b[2m\u001b[36m(pid=13380)\u001b[0m   File \"c:\\Users\\Public\\anaconda3\\lib\\site-packages\\ray\\tune\\function_runner.py\", line 328, in entrypoint\n",
      "\u001b[2m\u001b[36m(pid=13380)\u001b[0m     return self._trainable_func(self.config, self._status_reporter,\n",
      "\u001b[2m\u001b[36m(pid=13380)\u001b[0m   File \"c:\\Users\\Public\\anaconda3\\lib\\site-packages\\ray\\tune\\function_runner.py\", line 594, in _trainable_func\n",
      "\u001b[2m\u001b[36m(pid=13380)\u001b[0m     output = fn()\n",
      "\u001b[2m\u001b[36m(pid=13380)\u001b[0m   File \"<ipython-input-9-d9db0bddfedd>\", line 4, in my_func\n",
      "\u001b[2m\u001b[36m(pid=13380)\u001b[0m IndexError: tuple index out of range\n",
      "\u001b[2m\u001b[36m(pid=13380)\u001b[0m Exception in thread Thread-2:\n",
      "\u001b[2m\u001b[36m(pid=13380)\u001b[0m Traceback (most recent call last):\n",
      "\u001b[2m\u001b[36m(pid=13380)\u001b[0m   File \"c:\\Users\\Public\\anaconda3\\lib\\threading.py\", line 932, in _bootstrap_inner\n",
      "\u001b[2m\u001b[36m(pid=13380)\u001b[0m     self.run()\n",
      "\u001b[2m\u001b[36m(pid=13380)\u001b[0m   File \"c:\\Users\\Public\\anaconda3\\lib\\site-packages\\ray\\tune\\function_runner.py\", line 279, in run\n",
      "\u001b[2m\u001b[36m(pid=13380)\u001b[0m     raise e\n",
      "\u001b[2m\u001b[36m(pid=13380)\u001b[0m   File \"c:\\Users\\Public\\anaconda3\\lib\\site-packages\\ray\\tune\\function_runner.py\", line 260, in run\n",
      "\u001b[2m\u001b[36m(pid=13380)\u001b[0m     self._entrypoint()\n",
      "\u001b[2m\u001b[36m(pid=13380)\u001b[0m   File \"c:\\Users\\Public\\anaconda3\\lib\\site-packages\\ray\\tune\\function_runner.py\", line 328, in entrypoint\n",
      "\u001b[2m\u001b[36m(pid=13380)\u001b[0m     return self._trainable_func(self.config, self._status_reporter,\n",
      "\u001b[2m\u001b[36m(pid=13380)\u001b[0m   File \"c:\\Users\\Public\\anaconda3\\lib\\site-packages\\ray\\tune\\function_runner.py\", line 594, in _trainable_func\n",
      "\u001b[2m\u001b[36m(pid=13380)\u001b[0m     output = fn()\n",
      "\u001b[2m\u001b[36m(pid=13380)\u001b[0m   File \"<ipython-input-9-d9db0bddfedd>\", line 4, in my_func\n",
      "\u001b[2m\u001b[36m(pid=13380)\u001b[0m IndexError: tuple index out of range\n",
      "\u001b[2m\u001b[36m(pid=6732)\u001b[0m Windows fatal exception: access violation\n",
      "\u001b[2m\u001b[36m(pid=6732)\u001b[0m \n",
      "\u001b[2m\u001b[36m(pid=18572)\u001b[0m Windows fatal exception: access violation\n",
      "\u001b[2m\u001b[36m(pid=18572)\u001b[0m \n",
      "\u001b[2m\u001b[36m(pid=13380)\u001b[0m Windows fatal exception: access violation\n",
      "\u001b[2m\u001b[36m(pid=13380)\u001b[0m \n",
      "\u001b[2m\u001b[36m(pid=18288)\u001b[0m Windows fatal exception: access violation\n",
      "\u001b[2m\u001b[36m(pid=18288)\u001b[0m \n",
      "\u001b[2m\u001b[36m(pid=None)\u001b[0m [2022-05-10 04:41:10,848 C 10848 20712] asio.cc:88: redis_async_context_ must not be NULL\n",
      "\u001b[2m\u001b[36m(pid=None)\u001b[0m *** StackTrace Information ***\n",
      "\u001b[2m\u001b[36m(pid=None)\u001b[0m \n",
      "\u001b[2m\u001b[36m(pid=None)\u001b[0m [2022-05-10 04:41:17,937 C 19208 4068] redis_client.cc:87:  Check failed: under_retry_limit Expected 1 Redis shard addresses, found 3\n",
      "\u001b[2m\u001b[36m(pid=None)\u001b[0m *** StackTrace Information ***\n",
      "\u001b[2m\u001b[36m(pid=None)\u001b[0m \n",
      "2022-05-10 04:45:10,968\tWARNING worker.py:1215 -- The node with node id: 127f29d81b6346411060acc1dc63b4d402895c0bff96067030cdc42c and ip: 192.168.1.105 has been marked dead because the detector has missed too many heartbeats from it. This can happen when a raylet crashes unexpectedly or has lagging heartbeats.\n",
      "\u001b[2m\u001b[36m(pid=None)\u001b[0m [2022-05-10 04:46:33,963 C 23812 9128] redis_client.cc:87:  Check failed: under_retry_limit Expected 1 Redis shard addresses, found 4\n",
      "\u001b[2m\u001b[36m(pid=None)\u001b[0m *** StackTrace Information ***\n",
      "\u001b[2m\u001b[36m(pid=None)\u001b[0m \n",
      "\u001b[2m\u001b[36m(pid=21360)\u001b[0m Windows fatal exception: access violation\n",
      "\u001b[2m\u001b[36m(pid=21360)\u001b[0m \n",
      "\u001b[2m\u001b[36m(pid=18776)\u001b[0m Windows fatal exception: access violation\n",
      "\u001b[2m\u001b[36m(pid=18776)\u001b[0m \n",
      "\u001b[2m\u001b[36m(pid=2412)\u001b[0m Windows fatal exception: access violation\n",
      "\u001b[2m\u001b[36m(pid=2412)\u001b[0m \n",
      "\u001b[2m\u001b[36m(pid=11336)\u001b[0m Windows fatal exception: access violation\n",
      "\u001b[2m\u001b[36m(pid=11336)\u001b[0m \n",
      "\u001b[2m\u001b[36m(pid=None)\u001b[0m [2022-05-10 04:48:34,016 C 2716 20740] redis_client.cc:87:  Check failed: under_retry_limit Expected 1 Redis shard addresses, found 5\n",
      "\u001b[2m\u001b[36m(pid=None)\u001b[0m *** StackTrace Information ***\n",
      "\u001b[2m\u001b[36m(pid=None)\u001b[0m \n",
      "\u001b[2m\u001b[36m(pid=None)\u001b[0m [2022-05-10 04:49:58,335 C 21352 3960] redis_client.cc:87:  Check failed: under_retry_limit Expected 1 Redis shard addresses, found 8104303535147543913\n",
      "\u001b[2m\u001b[36m(pid=None)\u001b[0m *** StackTrace Information ***\n",
      "\u001b[2m\u001b[36m(pid=None)\u001b[0m \n"
     ]
    }
   ],
   "source": [
    "def my_func(config, reporter):  # add the reporter parameter\n",
    "      # report the configuration\n",
    "    clf = MLPClassifier(solver='lbfgs', alpha=config[\"alpha\"],\n",
    "                                            hidden_layer_sizes=config[\"hidden_layer_sizes\"],\n",
    "                                            max_iter=90000,activation='relu',random_state=1)\n",
    "    clf.fit(X_train, y_train)\n",
    "    y_pred = clf.predict(X_test)\n",
    "    reporter(config, mean_accuracy = accuracy_score(y_test, y_pred))\n",
    "    print(accuracy_score(y_test, y_pred))\n",
    "    \n",
    "tune.register_trainable(\"my_func\", my_func)\n",
    "ray.shutdown()\n",
    "ray.init()\n",
    "\n",
    "res = tune.run_experiments({\n",
    "    \"my_experiment\": {\n",
    "        \"run\": \"my_func\",\n",
    "        \"stop\": { \"mean_accuracy\": 0.6 },\n",
    "        \"config\": {\n",
    "            \"alpha\": tune.grid_search([0.1, 0.2]),\n",
    "            \"hidden_layer_sizes\": tune.grid_search([(5,2), (10,2)]),\n",
    "        }\n",
    "    }\n",
    "})"
   ]
  }
 ],
 "metadata": {
  "interpreter": {
   "hash": "7b9bf3d753fefe854781e52229fcc2b6d37fd5cec0eed166290fc2ac2cd3389d"
  },
  "kernelspec": {
   "display_name": "Python 3.8.8 ('base')",
   "language": "python",
   "name": "python3"
  },
  "language_info": {
   "codemirror_mode": {
    "name": "ipython",
    "version": 3
   },
   "file_extension": ".py",
   "mimetype": "text/x-python",
   "name": "python",
   "nbconvert_exporter": "python",
   "pygments_lexer": "ipython3",
   "version": "3.8.8"
  },
  "orig_nbformat": 4
 },
 "nbformat": 4,
 "nbformat_minor": 2
}
